Workbook
Name Cables: Lookup!$B$856:$B$1237
Name CREDIT_100G_PORT: #REF!
Name CREDIT_10G_PORT: #REF!
Name CREDIT_1G_POE_PORT: #REF!
Name CREDIT_1G_PORT: #REF!
Name CREDIT_2.5G_PORT: #REF!
Name CREDIT_25G_PORT: #REF!
Name CREDIT_40G_PORT: #REF!
Name CREDIT_5G_POE_PORT: #REF!
Name CREDIT_5G_PORT: #REF!
Name CURRENCY_TYPE: #REF!
Name Lookup_Master: Lookup!$B$7:$C$2418
Name M: Lookup!$B$7:$C$4180
Name MASETER: Lookup!$B$7:$C$2640
Name Master: Lookup!$B$7:$C$2640
Name Payment: Lookup!#REF!
Name Service: Lookup!$B$1311:$B$2408
Name Shipping: Lookup!$B$2409:$B$2418
Name ShippingOnQuote: #REF!
Name Software: Lookup!$B$1257:$B$1311
Name Switches: Lookup!$B$7:$B$855
Name VP_DISCOUNT: #REF!

Sheet 견적_Config
A5: Quotation
D7: Arista Networks Product Configurator - [Distributor Name / DVAR Name]
A10: Switches, APs, Appliances & Perpetual Licenses | L10: 0.85
A11: 제품 그룹 | B11: 제품 코드 | C11: 제품 상세 설명 | E11: 개월 | F11: 수량 | G11: 소비자가 | H11: 소비자합계가 | I11: 원가 | J11: 원가합계 | L11: 매출액 | M11: 정리 | N11: 합계
A12: Switches | B12: DCS-7050SX3-24YC4C-S-F | C12: =VLOOKUP(B12,Lookup!B:E,2,0) -> Arista 7050X3, 24x25GbE SFP & 4x100GbE QSFP switch, front-to-rear air, 2xAC | F12: 2 | G12: =VLOOKUP(B12,Lookup!B:E,3,0) -> 420453000 | H12: =G12*F12 -> 840906000 | I12: =ROUND(VLOOKUP(B12,Lookup!B:E,4,0),-3) -> 16457000 | J12: =I12*F12 -> 32914000 | L12: =I12/$L$10 -> 19361176 | M12: =ROUND(L12,-2) -> 19361200 | N12: =M12*F12 -> 38722400
A13: License | B13: LIC-FIX-2-E | C13: =VLOOKUP(B13,Lookup!$B$5:$C$4367,2,0) -> Enhanced L3 License for Arista Group 2 Fixed switches (BGP, OSPF, ISIS, PIM, NAT) | F13: 2 | G13: =VLOOKUP(B13,Lookup!B:E,3,0) -> 133664200 | H13: =G13*F13 -> 267328400 | I13: =ROUND(VLOOKUP(B13,Lookup!B:E,4,0),-3) -> 5242000 | J13: =I13*F13 -> 10484000 | L13: =I13/$L$10 -> 6167058.8 | M13: =ROUND(L13,-2) -> 6167100 | N13: =M13*F13 -> 12334200
A14: Switches | B14: CCS-720DT-24S-2F-EU | C14: =VLOOKUP(B14,Lookup!B:E,2,0) -> Arista 720DT, 24 x 1G, 4x10G SFP switch, front to rear air, 2 100W AC, EU Power Cord | F14: 1 | G14: =VLOOKUP(B14,Lookup!B:E,3,0) -> 102731700 | H14: =G14*F14 -> 102731700 | I14: =ROUND(VLOOKUP(B14,Lookup!B:E,4,0),-3) -> 4021000 | J14: =I14*F14 -> 4021000 | L14: =I14/$L$10 -> 4730588.2 | M14: =ROUND(L14,-2) -> 4730600 | N14: =M14*F14 -> 4730600
A15: Service | B15: SVC-7050SX3-24YC4CS-1M-NB | C15: =VLOOKUP(B15,Lookup!B:C,2,0) -> 1 Month A-Care Software & NBD Hardware Replacement/Same Day Ship for 7050SX3-24YC4C-S | E15: 12 | F15: 2 | G15: =VLOOKUP(B15,Lookup!B:E,3,0) -> 2804600 | H15: =G15*F15*E15 -> 67310400 | I15: =ROUND(VLOOKUP(B15,Lookup!B:E,4,0),-3) -> 208000 | J15: =I15*F15*E15 -> 4992000 | L15: =I15/$L$10 -> 244705.88 | M15: =ROUND(L15,-2) -> 244700 | N15: =M15*F15*E15 -> 5872800
A16: Service | B16: SVC-720DT-24S-1M-NB | C16: =VLOOKUP(B16,Lookup!B:C,2,0) -> 1-Month A-Care Software & NBD Hardware Replacement/Same Day Ship for CCS-720DT-24S series | E16: 12 | F16: 1 | G16: =VLOOKUP(B16,Lookup!B:E,3,0) -> 219300 | H16: =G16*F16*E16 -> 2631600 | I16: =ROUND(VLOOKUP(B16,Lookup!B:E,4,0),-3) -> 16000 | J16: =I16*F16*E16 -> 192000 | L16: =I16/$L$10 -> 18823.529 | M16: =ROUND(L16,-2) -> 18800 | N16: =M16*F16*E16 -> 225600
A19: Optics and Cables
A20: 제품 그룹 | B20: 제품 코드 | C20: 제품 상세 설명 | E20: 개월 | F20: 수량 | G20: 소비자가 | H20: 소비자합계가 | I20: 원가 | J20: 원가합계
A21: Optics | B21: QSFP-100G-LR | C21: =VLOOKUP(B21,Lookup!B:E,2,0) -> 100GBASE-LR QSFP Transceiver, up to 10km over duplex SMF | F21: 1 | G21: =VLOOKUP(B21,Lookup!B:E,3,0) -> 58870300 | H21: =G21*F21 -> 58870300 | I21: =ROUND(VLOOKUP(B21,Lookup!B:E,4,0),-3) -> 1868000 | J21: =I21*F21 -> 1868000
A22: Cable | B22: AOC-D-D-400G-10M | C22: =VLOOKUP(B22,Lookup!B:E,2,0) -> 400GbE QSFP-DD to QSFP-DD Active Optical Cable, 10 meter | F22: 1 | G22: =VLOOKUP(B22,Lookup!B:E,3,0) -> 184626200 | H22: =G22*F22 -> 184626200 | I22: =ROUND(VLOOKUP(B22,Lookup!B:E,4,0),-3) -> 7240000 | J22: =I22*F22 -> 7240000
A23: Optics | B23: LPO-800G-2FR4 | C23: =VLOOKUP(B23,Lookup!B:E,2,0) -> 2x 400GBASE-FR4 Linear Pluggable OSFP Transceiver, Dual LC, up to 2km over dual duplex SMF | F23: 1 | G23: =VLOOKUP(B23,Lookup!B:E,3,0) -> 177785600 | H23: =G23*F23 -> 177785600 | I23: =ROUND(VLOOKUP(B23,Lookup!B:E,4,0),-3) -> 5653000 | J23: =I23*F23 -> 5653000
A24: Optics | B24: OSFP-800G-2VSR4 | C24: =VLOOKUP(B24,Lookup!B:E,2,0) -> 2x 400GBASE-VSR4 OSFP Transceiver, dual MPO-12 APC connectors, up to 50m over parallel MMF | F24: 1 | G24: =VLOOKUP(B24,Lookup!B:E,3,0) -> 136998500 | H24: =G24*F24 -> 136998500 | I24: =ROUND(VLOOKUP(B24,Lookup!B:E,4,0),-3) -> 4348000 | J24: =I24*F24 -> 4348000
A25: Optics | B25: SFP-100M-FX | C25: =VLOOKUP(B25,Lookup!B:E,2,0) -> 100BASE-FX SFP Transceiver, up to 2km over duplex MMF. | F25: 1 | G25: =VLOOKUP(B25,Lookup!B:E,3,0) -> 6772100 | H25: =G25*F25 -> 6772100 | I25: =ROUND(VLOOKUP(B25,Lookup!B:E,4,0),-3) -> 215000 | J25: =I25*F25 -> 215000
A28: Software Subscriptions
A29: 제품 그룹 | B29: 제품 코드 | C29: 제품 상세 설명 | E29: 개월 | F29: 수량 | G29: 소비자가 | H29: 소비자합계가 | I29: 원가 | J29: 원가합계
A30: Subscription | B30: SS-CLOUDEOS-RR-CVS-10M-B-1M | C30: =VLOOKUP(B30,Lookup!B:E,2,0) -> CloudEOS Router for VM/Cloud SW Sub Lic for 1-Month, up to 10M routes with virtual route reflector feature, A-care Support, and 1-Month CloudVision as-a-Service for single instance | E30: 28 | F30: 1 | G30: =VLOOKUP(B30,Lookup!B:E,3,0) -> 17717000 | H30: =G30*F30*E30 -> 496076000 | I30: =ROUND(VLOOKUP(B30,Lookup!B:E,4,0),-3) -> 695000 | J30: =I30*F30*E30 -> 19460000
A31: Subscription | B31: SDE-ENT-HO-100G-1M | C31: =VLOOKUP(B31,Lookup!B:E,2,0) -> Arista VeloCloud SD-WAN Enterprise Edition (Hosted Orchestrator+Controller) - 100 Gbps | E31: 24 | F31: 1 | G31: =VLOOKUP(B31,Lookup!B:E,3,0) -> 106780800 | H31: =G31*F31*E31 -> 2562739200 | I31: =ROUND(VLOOKUP(B31,Lookup!B:E,4,0),-3) -> 4187000 | J31: =I31*F31*E31 -> 100488000
A35: Service and Support
A36: 제품 그룹 | B36: 제품 코드 | C36: 제품 상세 설명 | E36: 개월 | F36: 수량 | G36: 소비자가 | H36: 소비자합계가 | I36: 원가 | J36: 원가합계
A37: Service | B37: SVC-7010TX-48-1M-SHR | C37: =VLOOKUP(B37,Lookup!B:C,2,0) -> 1-Month Shared Service Contract for 7010TX-48, SW and NBD/Same Day Ship Replacement | E37: 12 | F37: 1 | G37: =VLOOKUP(B37,Lookup!B:E,3,0) -> 370100 | H37: =G37*F37*E37 -> 4441200 | I37: =ROUND(VLOOKUP(B37,Lookup!B:E,4,0),-3) -> 27000 | J37: =I37*F37*E37 -> 324000
A38: Service | B38: SVC-7050SX3-24YC4CS-1M-SHR | C38: =VLOOKUP(B38,Lookup!B:C,2,0) -> 1-Month Shared Service Contract for 7050SX3-24YC4C-S, SW and NBD/Same Day Ship Replacement | E38: 12 | F38: 1 | G38: =VLOOKUP(B38,Lookup!B:E,3,0) -> 1781900 | H38: =G38*F38*E38 -> 21382800 | I38: =ROUND(VLOOKUP(B38,Lookup!B:E,4,0),-3) -> 132000 | J38: =I38*F38*E38 -> 1584000
A39: Service | B39: SVC-7010TX-48-1M-SHR | C39: =VLOOKUP(B39,Lookup!B:C,2,0) -> 1-Month Shared Service Contract for 7010TX-48, SW and NBD/Same Day Ship Replacement | E39: 12 | F39: 1 | G39: =VLOOKUP(B39,Lookup!B:E,3,0) -> 370100 | H39: =G39*F39*E39 -> 4441200 | I39: =ROUND(VLOOKUP(B39,Lookup!B:E,4,0),-3) -> 27000 | J39: =I39*F39*E39 -> 324000
A40: Service | B40: SVC-7010TX-48-1M-SHR | C40: =VLOOKUP(B40,Lookup!B:C,2,0) -> 1-Month Shared Service Contract for 7010TX-48, SW and NBD/Same Day Ship Replacement | E40: 12 | F40: 1 | G40: =VLOOKUP(B40,Lookup!B:E,3,0) -> 370100 | H40: =G40*F40*E40 -> 4441200 | I40: =ROUND(VLOOKUP(B40,Lookup!B:E,4,0),-3) -> 27000 | J40: =I40*F40*E40 -> 324000
A41: Service | B41: SVC-7010TX-48-1M-SHR | C41: =VLOOKUP(B41,Lookup!B:C,2,0) -> 1-Month Shared Service Contract for 7010TX-48, SW and NBD/Same Day Ship Replacement | E41: 12 | F41: 1 | G41: =VLOOKUP(B41,Lookup!B:E,3,0) -> 370100 | H41: =G41*F41*E41 -> 4441200 | I41: =ROUND(VLOOKUP(B41,Lookup!B:E,4,0),-3) -> 27000 | J41: =I41*F41*E41 -> 324000
A44: 1. 위 견적서는 당사의 총판사 조건으로 산출되었습니다. | H44: VAT 별도 | I44: 원가 합계 | J44: =SUM(J11:J32) -> 191875000
A45: 2. 견적유효기간 : 견적 후 30일 | H45: VAT 포함 | I45: 원가 합계 | J45: =J44*1.1 -> 2.110625e+08
A46: 3. 12개월 하자보증서비스 조건

Sheet Lookup
C2: Korea List Price
E4: 총판 List Price 가격
A5: Category | B5: Product Number | C5: Description | D5: Disty_DVAR LP | E5: 총판 원가 (Partner) | F5: 구분
A6: 1 | B6: AP-W318-SS-5Y | C6: W-318 2x2:2 tri radio Wi-Fi 6E wall plate access point with internal antennas and 5 year Cognitive Cloud SW Subscription | D6: 26637100 | E6: 1044565.5 | F6: {=IF(TRIM(B6)="","", IF(SUMPRODUCT(COUNTIF(B6,{"AP-*"}))>0,"Access Point", IF(SUMPRODUCT(COUNTIF(B6,{"SVC-*","OSV-*"}))>0,"Service", IF(SUMPRODUCT(COUNTIF(B6,{"SS-*","SDEX-*","SDE-ENT-*","SDE-PRE2*","SDE-STD-*"}))>0,"Subscription", IF(SUMPRODUCT(COUNTIF(B6,{"SFP-*","QSFP-*","OSFP-*"}))>0,"Optic", IF(SUMPRODUCT(COUNTIF(B6,{"A-*","QDD-*","H-*","C-*","CAB-*","AOC-*"}))>0,"Cable", IF(SUMPRODUCT(COUNTIF(B6,{"DCS-*","CCS-*","PWR-*","KIT-*","FAN-*","GG*","DCA*","FB*","OC*","AWE*","5NB*","3NB*","7NB*","ZTX*","NIM*","JB*","SSD*"}))>0,"Switch", "기타")))))))} -> Access Point
A7: 1 | B7: AP-W318-SS-PREM-5Y | C7: W-318 2x2:2 tri radio Wi-Fi 6E wall plate access point with internal antennas and 5 year on-premises Cognitive Management Subscription | D7: 26637100 | E7: 1044565.5 | F7: Access Point
A8: 1 | B8: AP-W318-SS-3Y | C8: W-318 2x2:2 tri radio Wi-Fi 6E wall plate access point with internal antennas and 3 year Cognitive Cloud SW Subscription | D8: 20863600 | E8: 818162.5 | F8: Access Point
A9: 1 | B9: AP-W318-SS-PREM-3Y | C9: W-318 2x2:2 tri radio Wi-Fi 6E wall plate access point with internal antennas and 3 year on-premises Cognitive Management Subscription | D9: 20863600 | E9: 818162.5 | F9: Access Point
A10: 1 | B10: AP-W318 | C10: W-318 2x2:2 tri radio Wi-Fi 6E wall plate access point with internal antennas | D10: 12928600 | E10: 506992.5 | F10: Access Point
A11: 1 | B11: AP-W318-RW-SS-5Y | C11: Remote Workspaces bundle with W-318 2x2 Wi-Fi 6E wall plate AP, desktop stand, power supply, ethernet cable and 5 year cloud service | D11: 28073600 | E11: 1100898 | F11: Access Point
A12: 1 | B12: AP-W318-RW-SS-PREM-5Y | C12: Remote Workspaces hardware with W-318 2x2:2 tri radio Wi-Fi 6E wall plate access point with internal antennas and 5 year on-premises Cognitive Management Subscription | D12: 28073600 | E12: 1100898 | F12: Access Point
A13: 1 | B13: AP-W318-RW-SS-3Y | C13: Remote Workspaces bundle with W-318 2x2 Wi-Fi 6E wall plate AP, desktop stand, power supply, ethernet cable and 3 year cloud service | D13: 22300200 | E13: 874495 | F13: Access Point
A14: 1 | B14: AP-W318-RW-SS-PREM-3Y | C14: Remote Workspaces hardware with W-318 2x2:2 tri radio Wi-Fi 6E wall plate access point with internal antennas and 3 year on-premises Cognitive Management Subscription | D14: 22300200 | E14: 874495 | F14: Access Point
A15: 1 | B15: AP-W318-RW | C15: Remote Workspaces hardware with W-318 2x2 Wi-Fi 6E wall plate AP, desktop stand, power supply and ethernet cable | D15: 14365100 | E15: 563325 | F15: Access Point
A16: 1 | B16: AP-O435 | C16: O-435 Tri band 2x2:2 802.11be (WiFi 7) outdoor access point with internal antennas, 5 GbE interface and dedicated multi-function radio | D16: 36118100 | E16: 1416360 | F16: Access Point
A17: 1 | B17: AP-O435-SS-3Y | C17: O-435 Tri band 2x2:2 802.11be (WiFi 7) outdoor access point with internal antennas, 5 GbE interface and dedicated multi-function radio, and a 3-year cognitive cloud management subscription | D17: 44148800 | E17: 1731285.5 | F17: Access Point
A18: 1 | B18: AP-O435-SS-5Y | C18: O-435 Tri band 2x2:2 802.11be (WiFi 7) outdoor access point with internal antennas, 5 GbE interface and dedicated multi-function radio, and a 5-year cognitive cloud management subscription | D18: 49552900 | E18: 1943203 | F18: Access Point
... A5182: 5 | B5182: SVC-7020HR4M-10QC-4DF-1M-SH4 | C5182: 1-Month Shared Service Contract for 7020HR4M-10QC-4DF, SW and 24x7x4 Hour Replacement | D5182: 4175300 | E5182: 309575 | F5182: Service

Sheet Names Ranges_New
A3: Category | B3: Product Number | D3: Category | E3: Product Number | G3: Category | H3: Product Number | J3: Category | K3: Product Number
A4: 1 | B4: AP-C200 | D4: 3 | E4: A-D400-2Q200-10M | G4: 4 | H4: SS-CC-A-SSP-1M | J4: 5 | K4: OSV-7010T-1M-4H
B5: AP-C200-SS-3Y | E5: A-D400-2Q200-15M | H5: SS-CC-A-SXP-1M | K5: OSV-7010T-1M-NB
B6: AP-C200-SS-5Y | E6: A-D400-2Q200-1M | H6: SS-CC-A-SXP2-1M | K6: OSV-7010TDC-1M-4H
B7: AP-C200-SS-PREM-3Y | E7: A-D400-2Q200-20M | H7: SS-CC-MCD-1M | K7: OSV-7010TDC-1M-NB
B8: AP-C200-SS-PREM-5Y | E8: A-D400-2Q200-25M | H8: SS-CLOUDEOS-RR-CV-10M-B-1M | K8: OSV-7010TX-48-1M-4H
B9: AP-C230 | E9: A-D400-2Q200-30M | H9: SS-CLOUDEOS-RR-CVS-10M-B-1M | K9: OSV-7010TX-48-1M-NB
B10: AP-C230-SS-3Y | E10: A-D400-2Q200-3M | H10: SS-CLOUDEOS-VR-CV-100M-B-1M | K10: OSV-7010TX-48C-1M-4H
B11: AP-C230-SS-5Y | E11: A-D400-2Q200-5M | H11: SS-CLOUDEOS-VR-CV-10G-B-1M | K11: OSV-7010TX-48C-1M-NB
B12: AP-C230-SS-PREM-3Y | E12: A-D400-2Q200-7M | H12: SS-CLOUDEOS-VR-CV-1G-B-1M | K12: OSV-7010TX-48C-DC-1M-4H
B13: AP-C230-SS-PREM-5Y | E13: A-D400-Q400-10M | H13: SS-CLOUDEOS-VR-CVS-100M-B-1M | K13: OSV-7010TX-48C-DC-1M-NB
B14: AP-C230E | E14: A-D400-Q400-15M | H14: SS-CLOUDEOS-VR-CVS-10G-B-1M | K14: OSV-7010TX-48C-O3-1M-4H
B15: AP-C230E-SS-3Y | E15: A-D400-Q400-1M | H15: SS-CLOUDEOS-VR-CVS-1G-B-1M | K15: OSV-7010TX-48C-O3-1M-NB
B16: AP-C230E-SS-5Y | E16: A-D400-Q400-20M | H16: SS-CLOUDEOS-VZTX-CV-10G-B-1M | K16: OSV-7010TX-48C-O3A-1M-4H
... B422: DCS-7060DX5-64S# | E422: LPO-800G-DR8 | H422: SDEX-EFS-10M-1M | K422: SVC-7010TX-48C-O3-1M-2H
B423: DCS-7060PX4-32-F | E423: QDD-400G-ZR-EE | G423: 4 요약 | K423: SVC-7010TX-48C-O3-1M-4H
B424: DCS-7060PX4-32# | E424: QDD-400G-ER4 | G424: 총합계 | K424: SVC-7010TX-48C-O3-1M-NB
B425: DCS-7060PX5-64E-F | D425: 3 요약 | K425: SVC-7010TX-48C-O3-1M-SH4
B426: DCS-7060PX5-64E# | D426: 총합계 | K426: SVC-7010TX-48C-O3-1M-SHR
B427: DCS-7060SX2-48YC6-F | K427: SVC-7010TX-48C-O3A-1M-2H
B428: DCS-7060SX2-48YC6-R | K428: SVC-7010TX-48C-O3A-1M-4H
B429: DCS-7060SX2-48YC6# | K429: SVC-7010TX-48C-O3A-1M-NB
B430: DCS-7060X6-32PE-F | K430: SVC-7010TX-48C-O3A-1M-SH4
B431: DCS-7060X6-32PE# | K431: SVC-7010TX-48C-O3A-1M-SHR
B432: DCS-7060X6-64PE-F | K432: SVC-7010TX-48DC-1M-2H
B433: DCS-7060X6-64PE# | K433: SVC-7010TX-48DC-1M-4H
B434: DCS-7130-48EHS-F | K434: SVC-7010TX-48DC-1M-NB
B435: DCS-7130-48EHS-R | K435: SVC-7010TX-48DC-1M-SH4
B436: DCS-7130-48EHS# | K436: SVC-7010TX-48DC-1M-SHR
B437: DCS-7130-48G3S-F | K437: SVC-7020SR-24C2-1M-2H
B438: DCS-7130-48G3S-R | K438: SVC-7020SR-24C2-1M-4H
... B1606: DCS-7800R4K-36DE-LC# | K1606: SVE-S-PF-UCC-BASE-L3-R2
A1607: 1 요약 | K1607: SVE-S-PF-UCC-NODE-L3-R2
A1608: 총합계 | K1608: SVE-S-PF-UCC-BASE-L2-R2
K1609: SVE-S-PF-UCC-NODE-L2-R2
K1610: SVE-S-PF-UCC-ADD-CPI-R2
K1611: SVE-S-PF-UCC-BASE-L3-R3
K1612: SVE-S-PF-UCC-NODE-L3-R3
K1613: SVE-S-PF-UCC-BASE-L2-R3
K1614: SVE-S-PF-UCC-NODE-L2-R3
...

Sheet Oct_2026_New Products
A1: Product Number | B1: Description
A2: DCA-450-CV | B2: 1 unit CloudVision Physical Appliance, Model 450. Large Scale Compute Resource. 10G. Includes server sw. No device licenses.
A3: DCA-400-CV | B3: 1 unit CloudVision Physical Appliance, Model 400. Standard Compute Resource. 10G. Includes server sw. No device licenses.
A4: SVC-DCA-450-CV-1M-NB | B4: 1 Month A-Care Software & NBD Hardware Replacement/Same Day Ship for DCA-450-CV Appliance
A5: SVC-DCA-400-CV-1M-NB | B5: 1 Month A-Care Software & NBD Hardware Replacement/Same Day Ship for DCA-400-CV Appliance
A6: DCS-7909R5-BND | B6: Arista 7909R Chassis bundle. Includes 7909 chassis, 1x PCM, 9x 10kW PS, 3x power cables, 5x 7909FM-R5, 1x 7909-SUP-EL (Rack Kit)
A7: DCS-7909R5-BND-2S | B7: Arista 7909R Chassis bundle. Includes 7909 chassis, 1x PCM, 9x 10kW PS, 3x power cables, 5x 7909FM-R5, 2x 7909-SUP-EL (Rack Kit)
A8: DCS-7909R5-BND-12PS | B8: Arista 7909R Chassis bundle. Includes 7909 chassis, 1x PCM, 12x 10kW PS, 4x power cables, 5x 7909FM-R5, 1x 7909-SUP-EL (Rack Kit)
A9: DCS-7909R5-BND-2S-12PS | B9: Arista 7909R Chassis bundle. Includes 7909 chassis, 1x PCM, 12x 10kW PS, 4x power cables, 5x 7909FM-R5, 2x 7909-SUP-EL (Rack Kit)
A10: DCS-7909R5-BND-FLX | B10: Arista 7909R5 Chassis bundle. Includes 7909 chassis, 1x PCM, 9x 10kW PS, 3x Power cables, 5x 7909FM-R5, 1x 7909-SUP-EL, FLX Lic (Rack Kit)
A11: DCS-7909R5-BND-2S-12PS-FLX | B11: Arista 7909R5 Chassis bundle. Includes 7909 chassis, 1x PCM, 12x 10kW PS, 4x Power cables, 5x 7909FM-R5, 2x 7909-SUP-EL, FLX Lic (Rack Kit)
A12: DCS-7918R5-BND | B12: Arista 7918R Chassis bundle. Includes 7918 chassis, 1x PCM, 12x 10kW PS, 4x power cables, 5x 7918FM-R5, 1x 7918-SUP-EL (Rack Kit)
... A510: SDE-ENT-HO-500M-1M-EDU2 | B510: Arista VeloCloud SD-WAN Enterprise Edition (Hosted Orchestrator+Controller) - 500 Mbps
